Workbook
Name SegmentaçãodeDados_Mês: #N/A
Name SegmentaçãodeDados_Mês1: #N/A
Name SegmentaçãodeDados_Mês2: #N/A
Name SegmentaçãodeDados_Quinzena: #N/A
Name SegmentaçãodeDados_Quinzena1: #N/A
Name SegmentaçãodeDados_Selecione_o_Usuário: #N/A
Name SegmentaçãodeDados_Selecione_o_Usuário1: #N/A

Sheet Consolidado a Pagar
B1: NOTA: após confirmação de pagamento copiar a tabela abaixo como valores na aba histórico | K1: TODOS POSSUEM UM ADIANTAMENTO INICIAL DE 500,00 QUE SÓ SERÁ FINALIZADO QUANDO TIVER DESLIGAMENTO
B3: ='Por Supervisor'!$B$2&" "&'Por Supervisor'!$B$1 -> 1ª Quinzena SETEMBRO | K3: *Não precisa reembolso
B4: Matricula | C4: Nome | D4: FUNÇÃO | E4: C.Custo | F4: Valor KM | G4: Pedagio | H4: Estacionamento | I4: Diversas | J4: TT Reembolsavel | K4: Hotel* | L4: Adiantamento / Saldo | M4: Valor a depositar | N4: Obs
B5: MZ-322052 | C5: CAMILA CRISTINE ALTHOFF | D5: Supervisor | E5: 2907 | F5: =SUMIFS('Por Supervisor'!F:F,'Por Supervisor'!$A:$A,Tabela2[[#This Row],[Nome]]) -> 999.99 | G5: =SUMIFS('Por Supervisor'!G:G,'Por Supervisor'!$A:$A,Tabela2[[#This Row],[Nome]]) -> 28.5 | H5: =SUMIFS('Por Supervisor'!H:H,'Por Supervisor'!$A:$A,Tabela2[[#This Row],[Nome]]) -> 0 | I5: =SUMIFS('Por Supervisor'!I:I,'Por Supervisor'!$A:$A,Tabela2[[#This Row],[Nome]]) -> 43 | J5: =SUM(Tabela2[[#This Row],[Valor KM]:[Diversas]]) -> 1071.49 | K5: =SUMIFS('Por Supervisor'!K:K,'Por Supervisor'!$A:$A,Tabela2[[#This Row],[Nome]]) -> 0 | M5: =IF(AND(J5=0,Tabela2[[#This Row],[Adiantamento / Saldo]]=""),"-",(Tabela2[[#This Row],[TT Reembolsavel]]+Tabela2[[#This Row],[Adiantamento / Saldo]])) -> 1071.49
B6: MZ-331203 | C6: THAYS APARECIDA CARVALHO | D6: Supervisor | E6: 2907 | F6: =SUMIFS('Por Supervisor'!F:F,'Por Supervisor'!$A:$A,Tabela2[[#This Row],[Nome]]) -> 755.22 | G6: =SUMIFS('Por Supervisor'!G:G,'Por Supervisor'!$A:$A,Tabela2[[#This Row],[Nome]]) -> 0 | H6: =SUMIFS('Por Supervisor'!H:H,'Por Supervisor'!$A:$A,Tabela2[[#This Row],[Nome]]) -> 0 | I6: =SUMIFS('Por Supervisor'!I:I,'Por Supervisor'!$A:$A,Tabela2[[#This Row],[Nome]]) -> 0 | J6: =SUM(Tabela2[[#This Row],[Valor KM]:[Diversas]]) -> 755.22 | K6: =SUMIFS('Por Supervisor'!K:K,'Por Supervisor'!$A:$A,Tabela2[[#This Row],[Nome]]) -> 0 | M6: =IF(AND(J6=0,Tabela2[[#This Row],[Adiantamento / Saldo]]=""),"-",(Tabela2[[#This Row],[TT Reembolsavel]]+Tabela2[[#This Row],[Adiantamento / Saldo]])) -> 755.22
B7: MZ-335327 | C7: GEOVANA DUARTE FARIAS | D7: Supervisor | E7: 2907 | F7: =SUMIFS('Por Supervisor'!F:F,'Por Supervisor'!$A:$A,Tabela2[[#This Row],[Nome]]) -> 763.83 | G7: =SUMIFS('Por Supervisor'!G:G,'Por Supervisor'!$A:$A,Tabela2[[#This Row],[Nome]]) -> 5.7 | H7: =SUMIFS('Por Supervisor'!H:H,'Por Supervisor'!$A:$A,Tabela2[[#This Row],[Nome]]) -> 0 | I7: =SUMIFS('Por Supervisor'!I:I,'Por Supervisor'!$A:$A,Tabela2[[#This Row],[Nome]]) -> 0 | J7: =SUM(Tabela2[[#This Row],[Valor KM]:[Diversas]]) -> 769.53 | K7: =SUMIFS('Por Supervisor'!K:K,'Por Supervisor'!$A:$A,Tabela2[[#This Row],[Nome]]) -> 0 | M7: =IF(AND(J7=0,Tabela2[[#This Row],[Adiantamento / Saldo]]=""),"-",(Tabela2[[#This Row],[TT Reembolsavel]]+Tabela2[[#This Row],[Adiantamento / Saldo]])) -> 769.53
B8: MZ-332404 | C8: GUSTAVO MATHEUS DE OLIVEIRA | D8: Supervisor | E8: 2907 | F8: =SUMIFS('Por Supervisor'!F:F,'Por Supervisor'!$A:$A,Tabela2[[#This Row],[Nome]]) -> 313.65 | G8: =SUMIFS('Por Supervisor'!G:G,'Por Supervisor'!$A:$A,Tabela2[[#This Row],[Nome]]) -> 0 | H8: =SUMIFS('Por Supervisor'!H:H,'Por Supervisor'!$A:$A,Tabela2[[#This Row],[Nome]]) -> 0 | I8: =SUMIFS('Por Supervisor'!I:I,'Por Supervisor'!$A:$A,Tabela2[[#This Row],[Nome]]) -> 0 | J8: =SUM(Tabela2[[#This Row],[Valor KM]:[Diversas]]) -> 313.65 | K8: =SUMIFS('Por Supervisor'!K:K,'Por Supervisor'!$A:$A,Tabela2[[#This Row],[Nome]]) -> 0 | M8: =IF(AND(J8=0,Tabela2[[#This Row],[Adiantamento / Saldo]]=""),"-",(Tabela2[[#This Row],[TT Reembolsavel]]+Tabela2[[#This Row],[Adiantamento / Saldo]])) -> 313.65
B9: MZ-333609 | C9: MATHEUS DA SILVA MORAES | D9: Supervisor | E9: 2907 | F9: =SUMIFS('Por Supervisor'!F:F,'Por Supervisor'!$A:$A,Tabela2[[#This Row],[Nome]]) -> 687.57 | G9: =SUMIFS('Por Supervisor'!G:G,'Por Supervisor'!$A:$A,Tabela2[[#This Row],[Nome]]) -> 0 | H9: =SUMIFS('Por Supervisor'!H:H,'Por Supervisor'!$A:$A,Tabela2[[#This Row],[Nome]]) -> 0 | I9: =SUMIFS('Por Supervisor'!I:I,'Por Supervisor'!$A:$A,Tabela2[[#This Row],[Nome]]) -> 0 | J9: =SUM(Tabela2[[#This Row],[Valor KM]:[Diversas]]) -> 687.57 | K9: =SUMIFS('Por Supervisor'!K:K,'Por Supervisor'!$A:$A,Tabela2[[#This Row],[Nome]]) -> 0 | M9: =IF(AND(J9=0,Tabela2[[#This Row],[Adiantamento / Saldo]]=""),"-",(Tabela2[[#This Row],[TT Reembolsavel]]+Tabela2[[#This Row],[Adiantamento / Saldo]])) -> 687.57
B10: MZ-332790 | C10: RICARDO ALEXANDRE LOMBARDI | D10: Supervisor | E10: 2907 | F10: =SUMIFS('Por Supervisor'!F:F,'Por Supervisor'!$A:$A,Tabela2[[#This Row],[Nome]]) -> 321.03 | G10: =SUMIFS('Por Supervisor'!G:G,'Por Supervisor'!$A:$A,Tabela2[[#This Row],[Nome]]) -> 0 | H10: =SUMIFS('Por Supervisor'!H:H,'Por Supervisor'!$A:$A,Tabela2[[#This Row],[Nome]]) -> 0 | I10: =SUMIFS('Por Supervisor'!I:I,'Por Supervisor'!$A:$A,Tabela2[[#This Row],[Nome]]) -> 0 | J10: =SUM(Tabela2[[#This Row],[Valor KM]:[Diversas]]) -> 321.03 | K10: =SUMIFS('Por Supervisor'!K:K,'Por Supervisor'!$A:$A,Tabela2[[#This Row],[Nome]]) -> 0 | M10: =IF(AND(J10=0,Tabela2[[#This Row],[Adiantamento / Saldo]]=""),"-",(Tabela2[[#This Row],[TT Reembolsavel]]+Tabela2[[#This Row],[Adiantamento / Saldo]])) -> 321.03
B11: MZ-333502 | C11: SAIDDA KAULE ABDALA | D11: Coordenador | E11: 2907 | F11: =SUMIFS('Por Supervisor'!F:F,'Por Supervisor'!$A:$A,Tabela2[[#This Row],[Nome]]) -> 0 | G11: =SUMIFS('Por Supervisor'!G:G,'Por Supervisor'!$A:$A,Tabela2[[#This Row],[Nome]]) -> 0 | H11: =SUMIFS('Por Supervisor'!H:H,'Por Supervisor'!$A:$A,Tabela2[[#This Row],[Nome]]) -> 0 | I11: =SUMIFS('Por Supervisor'!I:I,'Por Supervisor'!$A:$A,Tabela2[[#This Row],[Nome]]) -> 0 | J11: =SUM(Tabela2[[#This Row],[Valor KM]:[Diversas]]) -> 0 | K11: =SUMIFS('Por Supervisor'!K:K,'Por Supervisor'!$A:$A,Tabela2[[#This Row],[Nome]]) -> 0 | M11: =IF(AND(J11=0,Tabela2[[#This Row],[Adiantamento / Saldo]]=""),"-",(Tabela2[[#This Row],[TT Reembolsavel]]+Tabela2[[#This Row],[Adiantamento / Saldo]])) -> -
B12: MZ-333871 | C12: CARLOS PROENÇA | D12: Supervisor | E12: 2907 | F12: =SUMIFS('Por Supervisor'!F:F,'Por Supervisor'!$A:$A,Tabela2[[#This Row],[Nome]]) -> 977.85 | G12: =SUMIFS('Por Supervisor'!G:G,'Por Supervisor'!$A:$A,Tabela2[[#This Row],[Nome]]) -> 33.8 | H12: =SUMIFS('Por Supervisor'!H:H,'Por Supervisor'!$A:$A,Tabela2[[#This Row],[Nome]]) -> 0 | I12: =SUMIFS('Por Supervisor'!I:I,'Por Supervisor'!$A:$A,Tabela2[[#This Row],[Nome]]) -> 0 | J12: =SUM(Tabela2[[#This Row],[Valor KM]:[Diversas]]) -> 1011.65 | M12: =IF(AND(J12=0,Tabela2[[#This Row],[Adiantamento / Saldo]]=""),"-",(Tabela2[[#This Row],[TT Reembolsavel]]+Tabela2[[#This Row],[Adiantamento / Saldo]])) -> 1011.65
B13: MZ-333812 | C13: JOÃO MARTINS NETO | D13: Supervisor | E13: 2907 | F13: =SUMIFS('Por Supervisor'!F:F,'Por Supervisor'!$A:$A,Tabela2[[#This Row],[Nome]]) -> 626.07 | G13: =SUMIFS('Por Supervisor'!G:G,'Por Supervisor'!$A:$A,Tabela2[[#This Row],[Nome]]) -> 11.4 | H13: =SUMIFS('Por Supervisor'!H:H,'Por Supervisor'!$A:$A,Tabela2[[#This Row],[Nome]]) -> 0 | I13: =SUMIFS('Por Supervisor'!I:I,'Por Supervisor'!$A:$A,Tabela2[[#This Row],[Nome]]) -> 0 | J13: =SUM(Tabela2[[#This Row],[Valor KM]:[Diversas]]) -> 637.47 | K13: =SUMIFS('Por Supervisor'!K:K,'Por Supervisor'!$A:$A,Tabela2[[#This Row],[Nome]]) -> 0 | M13: =IF(AND(J13=0,Tabela2[[#This Row],[Adiantamento / Saldo]]=""),"-",(Tabela2[[#This Row],[TT Reembolsavel]]+Tabela2[[#This Row],[Adiantamento / Saldo]])) -> 637.47
B14: MZ-327723 | C14: ANDERSON MICHALSKI FERREIRA | D14: Coordenador | E14: 2907 | F14: =SUMIFS('Por Supervisor'!F:F,'Por Supervisor'!$A:$A,Tabela2[[#This Row],[Nome]]) -> 0 | G14: =SUMIFS('Por Supervisor'!G:G,'Por Supervisor'!$A:$A,Tabela2[[#This Row],[Nome]]) -> 0 | H14: =SUMIFS('Por Supervisor'!H:H,'Por Supervisor'!$A:$A,Tabela2[[#This Row],[Nome]]) -> 0 | I14: =SUMIFS('Por Supervisor'!I:I,'Por Supervisor'!$A:$A,Tabela2[[#This Row],[Nome]]) -> 0 | J14: =SUM(Tabela2[[#This Row],[Valor KM]:[Diversas]]) -> 0 | K14: =SUMIFS('Por Supervisor'!K:K,'Por Supervisor'!$A:$A,Tabela2[[#This Row],[Nome]]) -> 0 | M14: =IF(AND(J14=0,Tabela2[[#This Row],[Adiantamento / Saldo]]=""),"-",(Tabela2[[#This Row],[TT Reembolsavel]]+Tabela2[[#This Row],[Adiantamento / Saldo]])) -> -
F15: =SUMIFS('Por Supervisor'!F:F,'Por Supervisor'!$A:$A,Tabela2[[#This Row],[Nome]]) -> 0 | G15: =SUMIFS('Por Supervisor'!G:G,'Por Supervisor'!$A:$A,Tabela2[[#This Row],[Nome]]) -> 0 | H15: =SUMIFS('Por Supervisor'!H:H,'Por Supervisor'!$A:$A,Tabela2[[#This Row],[Nome]]) -> 0 | I15: =SUMIFS('Por Supervisor'!I:I,'Por Supervisor'!$A:$A,Tabela2[[#This Row],[Nome]]) -> 0 | J15: =SUM(Tabela2[[#This Row],[Valor KM]:[Diversas]]) -> 0 | K15: =SUMIFS('Por Supervisor'!K:K,'Por Supervisor'!$A:$A,Tabela2[[#This Row],[Nome]]) -> 0 | M15: =IF(AND(J15=0,Tabela2[[#This Row],[Adiantamento / Saldo]]=""),"-",(Tabela2[[#This Row],[TT Reembolsavel]]+Tabela2[[#This Row],[Adiantamento / Saldo]])) -> -
F16: =SUMIFS('Por Supervisor'!F:F,'Por Supervisor'!$A:$A,Tabela2[[#This Row],[Nome]]) -> 0 | G16: =SUMIFS('Por Supervisor'!G:G,'Por Supervisor'!$A:$A,Tabela2[[#This Row],[Nome]]) -> 0 | H16: =SUMIFS('Por Supervisor'!H:H,'Por Supervisor'!$A:$A,Tabela2[[#This Row],[Nome]]) -> 0 | I16: =SUMIFS('Por Supervisor'!I:I,'Por Supervisor'!$A:$A,Tabela2[[#This Row],[Nome]]) -> 0 | J16: =SUM(Tabela2[[#This Row],[Valor KM]:[Diversas]]) -> 0 | K16: =SUMIFS('Por Supervisor'!K:K,'Por Supervisor'!$A:$A,Tabela2[[#This Row],[Nome]]) -> 0 | M16: =IF(AND(J16=0,Tabela2[[#This Row],[Adiantamento / Saldo]]=""),"-",(Tabela2[[#This Row],[TT Reembolsavel]]+Tabela2[[#This Row],[Adiantamento / Saldo]])) -> -
J17: =SUBTOTAL(109,Tabela2[TT Reembolsavel]) -> 5567.61 | M17: =SUBTOTAL(109,Tabela2[Valor a depositar]) -> 5567.61

Sheet Por Supervisor
A1: Mês | B1: SETEMBRO
A2: Quinzena | B2: 1ª Quinzena
A4: Selecione o Usuário | B4: Data | C4: KM inicial | D4: KM final | E4: KM Rodado | F4: Valor KM | G4: Pedágio $ | H4: Estacionamento $ | I4: Diversas $ | J4: Valor reembolsavel | K4: Hospedagem $
A5: Geovana Duarte Farias | B5: 46267 | C5: 137264 | D5: 137535 | E5: 271 | F5: 333.33 | G5: 5.7 | H5: 0 | I5: 0 | J5: 339.03 | K5: 0
A6: Geovana Duarte Farias | B6: 46268 | C6: 137535 | D6: 137607 | E6: 72 | F6: 88.56 | G6: 0 | H6: 0 | I6: 0 | J6: 88.56 | K6: 0
A7: Geovana Duarte Farias | B7: 46269 | C7: 137607 | D7: 137672 | E7: 65 | F7: 79.95 | G7: 0 | H7: 0 | I7: 0 | J7: 79.95 | K7: 0
A8: Geovana Duarte Farias | B8: 46273 | C8: 137727 | D8: 137804 | E8: 77 | F8: 94.71 | G8: 0 | H8: 0 | I8: 0 | J8: 94.71 | K8: 0
A9: Geovana Duarte Farias | B9: 46274 | C9: 137804 | D9: 137852 | E9: 48 | F9: 59.04 | G9: 0 | H9: 0 | I9: 0 | J9: 59.04 | K9: 0
A10: Geovana Duarte Farias | B10: 46280 | C10: 138221 | D10: 138309 | E10: 88 | F10: 108.24 | G10: 0 | H10: 0 | I10: 0 | J10: 108.24 | K10: 0
A11: Geovana Duarte Farias Total | F11: 763.83 | G11: 5.7 | H11: 0 | I11: 0 | J11: 769.53 | K11: 0
A12: CAMILA CRISTINE ALTHOFF | B12: 46266 | C12: 198047 | D12: 198102 | E12: 55 | F12: 67.65 | G12: 0 | H12: 0 | I12: 0 | J12: 67.65 | K12: 0
A13: CAMILA CRISTINE ALTHOFF | B13: 46267 | C13: 198102 | D13: 198175 | E13: 73 | F13: 89.79 | G13: 0 | H13: 0 | I13: 0 | J13: 89.79 | K13: 0
A14: CAMILA CRISTINE ALTHOFF | B14: 46268 | C14: 198175 | D14: 198212 | E14: 37 | F14: 45.51 | G14: 0 | H14: 0 | I14: 0 | J14: 45.51 | K14: 0
A15: CAMILA CRISTINE ALTHOFF | B15: 46269 | C15: 198212 | D15: 198255 | E15: 43 | F15: 52.89 | G15: 0 | H15: 0 | I15: 0 | J15: 52.89 | K15: 0
A16: CAMILA CRISTINE ALTHOFF | B16: 46273 | C16: 198280 | D16: 198693 | E16: 413 | F16: 507.99 | G16: 28.5 | H16: 0 | I16: 43 | J16: 579.49 | K16: 0
A17: CAMILA CRISTINE ALTHOFF | B17: 46274 | C17: 198693 | D17: 198766 | E17: 73 | F17: 89.79 | G17: 0 | H17: 0 | I17: 0 | J17: 89.79 | K17: 0
A18: CAMILA CRISTINE ALTHOFF | B18: 46276 | C18: 198766 | D18: 198841 | E18: 75 | F18: 92.25 | G18: 0 | H18: 0 | I18: 0 | J18: 92.25 | K18: 0
A19: CAMILA CRISTINE ALTHOFF | B19: 46277 | C19: 198841 | D19: 198876 | E19: 35 | F19: 43.05 | G19: 0 | H19: 0 | I19: 0 | J19: 43.05 | K19: 0
A20: CAMILA CRISTINE ALTHOFF | B20: 46280 | C20: 198901 | D20: 198910 | E20: 9 | F20: 11.07 | G20: 0 | H20: 0 | I20: 0 | J20: 11.07 | K20: 0
A21: CAMILA CRISTINE ALTHOFF Total | F21: 999.99 | G21: 28.5 | H21: 0 | I21: 43 | J21: 1071.49 | K21: 0
A22: GUSTAVO MATHEUS DE OLIVEIRA | B22: 46280 | C22: 178367 | D22: 178622 | E22: 255 | F22: 313.65 | G22: 0 | H22: 0 | I22: 0 | J22: 313.65 | K22: 0
A23: GUSTAVO MATHEUS DE OLIVEIRA Total | F23: 313.65 | G23: 0 | H23: 0 | I23: 0 | J23: 313.65 | K23: 0
A24: RICARDO ALEXANDRE LOMBARDI | B24: 46273 | C24: 135217 | D24: 135269 | E24: 52 | F24: 63.96 | G24: 0 | H24: 0 | I24: 0 | J24: 63.96 | K24: 0
A25: RICARDO ALEXANDRE LOMBARDI | B25: 46274 | C25: 135269 | D25: 135400 | E25: 131 | F25: 161.13 | G25: 0 | H25: 0 | I25: 0 | J25: 161.13 | K25: 0
A26: RICARDO ALEXANDRE LOMBARDI | B26: 46276 | C26: 135511 | D26: 135555 | E26: 44 | F26: 54.12 | G26: 0 | H26: 0 | I26: 0 | J26: 54.12 | K26: 0
A27: RICARDO ALEXANDRE LOMBARDI | B27: 46279 | C27: 135669 | D27: 135703 | E27: 34 | F27: 41.82 | G27: 0 | H27: 0 | I27: 0 | J27: 41.82 | K27: 0
A28: RICARDO ALEXANDRE LOMBARDI Total | F28: 321.03 | G28: 0 | H28: 0 | I28: 0 | J28: 321.03 | K28: 0
A29: MATHEUS DA SILVA MORAES | B29: 46266 | C29: 137979 | D29: 138138 | E29: 85 | F29: 104.55 | G29: 0 | H29: 0 | I29: 0 | J29: 104.55 | K29: 0
A30: MATHEUS DA SILVA MORAES | B30: 46267 | C30: 138138 | D30: 138256 | E30: 118 | F30: 145.14 | G30: 0 | H30: 0 | I30: 0 | J30: 145.14 | K30: 0
A31: MATHEUS DA SILVA MORAES | B31: 46274 | C31: 138585 | D31: 138807 | E31: 222 | F31: 273.06 | G31: 0 | H31: 0 | I31: 0 | J31: 273.06 | K31: 0
A32: MATHEUS DA SILVA MORAES | B32: 46275 | C32: 138807 | D32: 138941 | E32: 134 | F32: 164.82 | G32: 0 | H32: 0 | I32: 0 | J32: 164.82 | K32: 0
A33: MATHEUS DA SILVA MORAES Total | F33: 687.57 | G33: 0 | H33: 0 | I33: 0 | J33: 687.57 | K33: 0
A34: CARLOS PROENÇA | B34: 46269 | C34: 56611 | D34: 57011 | E34: 400 | F34: 492 | G34: 23.4 | H34: 0 | I34: 0 | J34: 515.4 | K34: 0
A35: CARLOS PROENÇA | B35: 46274 | C35: 57684 | D35: 58079 | E35: 395 | F35: 485.85 | G35: 10.4 | H35: 0 | I35: 0 | J35: 496.25 | K35: 0
A36: CARLOS PROENÇA Total | F36: 977.85 | G36: 33.8 | H36: 0 | I36: 0 | J36: 1011.65 | K36: 0
A37: JOÃO MARTINS NETO | B37: 46266 | C37: 110218 | D37: 110316 | E37: 98 | F37: 120.54 | G37: 0 | H37: 0 | I37: 0 | J37: 120.54 | K37: 0
A38: JOÃO MARTINS NETO | B38: 46273 | C38: 110616 | D38: 110668 | E38: 52 | F38: 63.96 | G38: 0 | H38: 0 | I38: 0 | J38: 63.96 | K38: 0
A39: JOÃO MARTINS NETO | B39: 46274 | C39: 110668 | D39: 110811 | E39: 143 | F39: 175.89 | G39: 11.4 | H39: 0 | I39: 0 | J39: 187.29 | K39: 0
A40: JOÃO MARTINS NETO | B40: 46275 | C40: 110812 | D40: 110916 | E40: 104 | F40: 127.92 | G40: 0 | H40: 0 | I40: 0 | J40: 127.92 | K40: 0
A41: JOÃO MARTINS NETO | B41: 46280 | C41: 110965 | D41: 111077 | E41: 112 | F41: 137.76 | G41: 0 | H41: 0 | I41: 0 | J41: 137.76 | K41: 0
...

Sheet Pesquisa
A1: Carimbo de data/hora | B1: Endereço de e-mail | C1: Selecione o Usuário | D1: Informe a placa do veículo | E1: Informe a data | F1: Informe o KM inicial do dia | G1: Insira a foto do hodômetro inicial | H1: Informe o KM final do dia | I1: Insira a foto do hodômetro final | J1: Quais lojas você visitou? | K1: Caso tenha rodado particular alguma parte do trajeto, informe o total de KM a ser deduzido. | L1: Possui despesas a serem lançadas | M1: Pedágio | N1: Insira as fotos dos recibos de pedágio | O1: Estacionamento | P1: Insira as fotos dos recibos de estacionamento | Q1: Despesas Diversas (Jantar em viagem, Impressões, Etc) | R1: Insira as fotos das notas de outras despesas | S1: Hospedagem | T1: Caso possua alguma observação sobre as despesas favor informar | U1: KM Rodado | V1: Valor KM | W1: Pedágio $ | X1: Estacionamento $ | Y1: Diversas $ | Z1: Hospedagem $ | AA1: Quinzena | AB1: Mês | AC1: Filtro mês dia
A2: 46034.351 | B2: sussuazevedo.com@icloud.com | C2: SUELEN DOS SANTOS AZEVEDO | D2: MFW6D17 | E2: 46024 | F2: 105642 | G2: https://drive.google.com/open?id=1KYNmN07uoNR2n42B3FXEHGxaV6cLYPEG | H2: 105788 | I2: https://drive.google.com/open?id=1m19T-228b0cuj3S9Zr2krHBB_ogorrGk | J2: Carrefour, Koch floripa, Komprão 55 | L2: Não | U2: =(Tabela1[[#This Row],[Informe o KM final do dia]]-Tabela1[[#This Row],[Informe o KM inicial do dia]])-Tabela1[[#This Row],[Caso tenha rodado particular alguma parte do trajeto, informe o total de KM a ser deduzido.]] -> 146 | V2: =IF(Tabela1[[#This Row],[Informe a data]]<DATE(2026,3,16), Tabela1[[#This Row],[KM Rodado]]*1.1, Tabela1[[#This Row],[KM Rodado]]*1.23) -> 160.6 | W2: =IFERROR(SUBSTITUTE(Tabela1[[#This Row],[Pedágio]],".",",",1)*1,0) -> 0 | X2: =IFERROR(SUBSTITUTE(Tabela1[[#This Row],[Estacionamento]],".",",",1)*1,0) -> 0 | Y2: =IFERROR(SUBSTITUTE(Tabela1[[#This Row],[Despesas Diversas (Jantar em viagem, Impressões, Etc)]],".",",",1)*1,0) -> 0 | Z2: =IFERROR(SUBSTITUTE(Tabela1[[#This Row],[Hospedagem]],".",",",1)*1,0) -> 0 | AA2: =IF(DAY(Tabela1[[#This Row],[Informe a data]])<=15,"1ª Quinzena","2ª Quinzena") -> 1ª Quinzena | AB2: =UPPER(TEXT(Tabela1[[#This Row],[Informe a data]],"mmmm")) -> JANEIRO | AC2: =_xlfn.CONCAT(Tabela1[[#This Row],[Selecione o Usuário]]," - ",TEXT(Tabela1[[#This Row],[Informe a data]],"dd-mm-aa")) -> #NAME?
A3: 46031.608 | B3: vinicioskerber@gmail.com | C3: VINICIUS ROBERTO KERBER | D3: MHO9G63 | E3: 46024 | F3: 212986 | G3: https://drive.google.com/open?id=1qYI936hO5BKGjC-5APmVsr8w2BOKfpwu | H3: 213022 | I3: https://drive.google.com/open?id=1vS2ku8_7ioiRf7PO1ekIz9WeuBJZhzQ6 | J3: Cooper Garcia, cooper Glória | L3: Não | U3: =(Tabela1[[#This Row],[Informe o KM final do dia]]-Tabela1[[#This Row],[Informe o KM inicial do dia]])-Tabela1[[#This Row],[Caso tenha rodado particular alguma parte do trajeto, informe o total de KM a ser deduzido.]] -> 36 | V3: =IF(Tabela1[[#This Row],[Informe a data]]<DATE(2026,3,16), Tabela1[[#This Row],[KM Rodado]]*1.1, Tabela1[[#This Row],[KM Rodado]]*1.23) -> 39.6 | W3: =IFERROR(SUBSTITUTE(Tabela1[[#This Row],[Pedágio]],".",",",1)*1,0) -> 0 | X3: =IFERROR(SUBSTITUTE(Tabela1[[#This Row],[Estacionamento]],".",",",1)*1,0) -> 0 | Y3: =IFERROR(SUBSTITUTE(Tabela1[[#This Row],[Despesas Diversas (Jantar em viagem, Impressões, Etc)]],".",",",1)*1,0) -> 0 | Z3: =IFERROR(SUBSTITUTE(Tabela1[[#This Row],[Hospedagem]],".",",",1)*1,0) -> 0 | AA3: =IF(DAY(Tabela1[[#This Row],[Informe a data]])<=15,"1ª Quinzena","2ª Quinzena") -> 1ª Quinzena | AB3: =UPPER(TEXT(Tabela1[[#This Row],[Informe a data]],"mmmm")) -> JANEIRO | AC3: =_xlfn.CONCAT(Tabela1[[#This Row],[Selecione o Usuário]]," - ",TEXT(Tabela1[[#This Row],[Informe a data]],"dd-mm-aa")) -> #NAME?
A4: 46027.96 | B4: sabrina.pires@mazzini.com.br | C4: SABRINA DOS SANTOS PIRES | D4: AZC9E32 | E4: 46027 | F4: 172770 | G4: https://drive.google.com/open?id=1UavfH0mE7m_A6j4phdWhnux6CiTCGnX_ | H4: 172848 | I4: https://drive.google.com/open?id=1vNdIFFWbay4r8_xDZC5GHaqwts-29CFf | J4: Fort 130 Brasil atacadista Fort campeche | L4: Não | U4: =(Tabela1[[#This Row],[Informe o KM final do dia]]-Tabela1[[#This Row],[Informe o KM inicial do dia]])-Tabela1[[#This Row],[Caso tenha rodado particular alguma parte do trajeto, informe o total de KM a ser deduzido.]] -> 78 | V4: =IF(Tabela1[[#This Row],[Informe a data]]<DATE(2026,3,16), Tabela1[[#This Row],[KM Rodado]]*1.1, Tabela1[[#This Row],[KM Rodado]]*1.23) -> 85.8 | W4: =IFERROR(SUBSTITUTE(Tabela1[[#This Row],[Pedágio]],".",",",1)*1,0) -> 0 | X4: =IFERROR(SUBSTITUTE(Tabela1[[#This Row],[Estacionamento]],".",",",1)*1,0) -> 0 | Y4: =IFERROR(SUBSTITUTE(Tabela1[[#This Row],[Despesas Diversas (Jantar em viagem, Impressões, Etc)]],".",",",1)*1,0) -> 0 | Z4: =IFERROR(SUBSTITUTE(Tabela1[[#This Row],[Hospedagem]],".",",",1)*1,0) -> 0 | AA4: =IF(DAY(Tabela1[[#This Row],[Informe a data]])<=15,"1ª Quinzena","2ª Quinzena") -> 1ª Quinzena | AB4: =UPPER(TEXT(Tabela1[[#This Row],[Informe a data]],"mmmm")) -> JANEIRO | AC4: =_xlfn.CONCAT(Tabela1[[#This Row],[Selecione o Usuário]]," - ",TEXT(Tabela1[[#This Row],[Informe a data]],"dd-mm-aa")) -> #NAME?
A5: 46028.782 | B5: camila.althoff@mazzini.com.br | C5: CAMILA CRISTINE ALTHOFF | D5: Mlz4j72 | E5: 46028 | F5: 185450 | G5: https://drive.google.com/open?id=18j1kKdkPpHMRosNYZAJHGmUmZ-en4RmC | H5: 185504 | I5: https://drive.google.com/open?id=1ckMfdiuOwMXCAWy01Fz4SQZ-dlyZfvN2 | J5: Fort 365, Fort jardim atlântico, Zeus brasil | L5: Não | U5: =(Tabela1[[#This Row],[Informe o KM final do dia]]-Tabela1[[#This Row],[Informe o KM inicial do dia]])-Tabela1[[#This Row],[Caso tenha rodado particular alguma parte do trajeto, informe o total de KM a ser deduzido.]] -> 54 | V5: =IF(Tabela1[[#This Row],[Informe a data]]<DATE(2026,3,16), Tabela1[[#This Row],[KM Rodado]]*1.1, Tabela1[[#This Row],[KM Rodado]]*1.23) -> 59.4 | W5: =IFERROR(SUBSTITUTE(Tabela1[[#This Row],[Pedágio]],".",",",1)*1,0) -> 0 | X5: =IFERROR(SUBSTITUTE(Tabela1[[#This Row],[Estacionamento]],".",",",1)*1,0) -> 0 | Y5: =IFERROR(SUBSTITUTE(Tabela1[[#This Row],[Despesas Diversas (Jantar em viagem, Impressões, Etc)]],".",",",1)*1,0) -> 0 | Z5: =IFERROR(SUBSTITUTE(Tabela1[[#This Row],[Hospedagem]],".",",",1)*1,0) -> 0 | AA5: =IF(DAY(Tabela1[[#This Row],[Informe a data]])<=15,"1ª Quinzena","2ª Quinzena") -> 1ª Quinzena | AB5: =UPPER(TEXT(Tabela1[[#This Row],[Informe a data]],"mmmm")) -> JANEIRO | AC5: =_xlfn.CONCAT(Tabela1[[#This Row],[Selecione o Usuário]]," - ",TEXT(Tabela1[[#This Row],[Informe a data]],"dd-mm-aa")) -> #NAME?
A6: 46031.977 | B6: lombardi2025@gmail.com | C6: RICARDO ALEXANDRE LOMBARDI | D6: OWA4C07 | E6: 46028 | F6: 167575 | G6: https://drive.google.com/open?id=1xZ5kqU8hTlxlUIG4gcOqyO9CYGa27za2 | H6: 167625 | I6: https://drive.google.com/open?id=1vloXVEfCOLF22v-lv7GwtqsWtcfbl8u2 | J6: Komprao 77, komprao 45, imperatriz,komprao 59 | L6: Não | U6: =(Tabela1[[#This Row],[Informe o KM final do dia]]-Tabela1[[#This Row],[Informe o KM inicial do dia]])-Tabela1[[#This Row],[Caso tenha rodado particular alguma parte do trajeto, informe o total de KM a ser deduzido.]] -> 50 | V6: =IF(Tabela1[[#This Row],[Informe a data]]<DATE(2026,3,16), Tabela1[[#This Row],[KM Rodado]]*1.1, Tabela1[[#This Row],[KM Rodado]]*1.23) -> 55 | W6: =IFERROR(SUBSTITUTE(Tabela1[[#This Row],[Pedágio]],".",",",1)*1,0) -> 0 | X6: =IFERROR(SUBSTITUTE(Tabela1[[#This Row],[Estacionamento]],".",",",1)*1,0) -> 0 | Y6: =IFERROR(SUBSTITUTE(Tabela1[[#This Row],[Despesas Diversas (Jantar em viagem, Impressões, Etc)]],".",",",1)*1,0) -> 0 | Z6: =IFERROR(SUBSTITUTE(Tabela1[[#This Row],[Hospedagem]],".",",",1)*1,0) -> 0 | AA6: =IF(DAY(Tabela1[[#This Row],[Informe a data]])<=15,"1ª Quinzena","2ª Quinzena") -> 1ª Quinzena | AB6: =UPPER(TEXT(Tabela1[[#This Row],[Informe a data]],"mmmm")) -> JANEIRO | AC6: =_xlfn.CONCAT(Tabela1[[#This Row],[Selecione o Usuário]]," - ",TEXT(Tabela1[[#This Row],[Informe a data]],"dd-mm-aa")) -> #NAME?
A7: 46034.354 | B7: sussuazevedo.com@icloud.com | C7: SUELEN DOS SANTOS AZEVEDO | D7: MFW6D17 | E7: 46028 | F7: 105821 | G7: https://drive.google.com/open?id=1omA_eXctjnr4WwIoiJtXIzC1BToGua8d | H7: 105831 | I7: https://drive.google.com/open?id=1WYlS12BXIZAs5iNxNA-PkcV2_4ZI0Q3G | J7: Fui ao Komprão 18 e ao Koch 4 | L7: Não | U7: =(Tabela1[[#This Row],[Informe o KM final do dia]]-Tabela1[[#This Row],[Informe o KM inicial do dia]])-Tabela1[[#This Row],[Caso tenha rodado particular alguma parte do trajeto, informe o total de KM a ser deduzido.]] -> 10 | V7: =IF(Tabela1[[#This Row],[Informe a data]]<DATE(2026,3,16), Tabela1[[#This Row],[KM Rodado]]*1.1, Tabela1[[#This Row],[KM Rodado]]*1.23) -> 11 | W7: =IFERROR(SUBSTITUTE(Tabela1[[#This Row],[Pedágio]],".",",",1)*1,0) -> 0 | X7: =IFERROR(SUBSTITUTE(Tabela1[[#This Row],[Estacionamento]],".",",",1)*1,0) -> 0 | Y7: =IFERROR(SUBSTITUTE(Tabela1[[#This Row],[Despesas Diversas (Jantar em viagem, Impressões, Etc)]],".",",",1)*1,0) -> 0 | Z7: =IFERROR(SUBSTITUTE(Tabela1[[#This Row],[Hospedagem]],".",",",1)*1,0) -> 0 | AA7: =IF(DAY(Tabela1[[#This Row],[Informe a data]])<=15,"1ª Quinzena","2ª Quinzena") -> 1ª Quinzena | AB7: =UPPER(TEXT(Tabela1[[#This Row],[Informe a data]],"mmmm")) -> JANEIRO | AC7: =_xlfn.CONCAT(Tabela1[[#This Row],[Selecione o Usuário]]," - ",TEXT(Tabela1[[#This Row],[Informe a data]],"dd-mm-aa")) -> #NAME?
A8: 46031.61 | B8: vinicioskerber@gmail.com | C8: VINICIUS ROBERTO KERBER | D8: MHO9G63 | E8: 46028 | F8: 213548 | G8: https://drive.google.com/open?id=1kgu6lQ88Apv7GUU-4P17QGOmrAYG9kED | H8: 213630 | I8: https://drive.google.com/open?id=1l7XIxsTEwJX90j8_8ePvLYLoXg12_AM5 | J8: Komprao 40, top 104, Cooper Omino, super A | L8: Não | U8: =(Tabela1[[#This Row],[Informe o KM final do dia]]-Tabela1[[#This Row],[Informe o KM inicial do dia]])-Tabela1[[#This Row],[Caso tenha rodado particular alguma parte do trajeto, informe o total de KM a ser deduzido.]] -> 82 | V8: =IF(Tabela1[[#This Row],[Informe a data]]<DATE(2026,3,16), Tabela1[[#This Row],[KM Rodado]]*1.1, Tabela1[[#This Row],[KM Rodado]]*1.23) -> 90.2 | W8: =IFERROR(SUBSTITUTE(Tabela1[[#This Row],[Pedágio]],".",",",1)*1,0) -> 0 | X8: =IFERROR(SUBSTITUTE(Tabela1[[#This Row],[Estacionamento]],".",",",1)*1,0) -> 0 | Y8: =IFERROR(SUBSTITUTE(Tabela1[[#This Row],[Despesas Diversas (Jantar em viagem, Impressões, Etc)]],".",",",1)*1,0) -> 0 | Z8: =IFERROR(SUBSTITUTE(Tabela1[[#This Row],[Hospedagem]],".",",",1)*1,0) -> 0 | AA8: =IF(DAY(Tabela1[[#This Row],[Informe a data]])<=15,"1ª Quinzena","2ª Quinzena") -> 1ª Quinzena | AB8: =UPPER(TEXT(Tabela1[[#This Row],[Informe a data]],"mmmm")) -> JANEIRO | AC8: =_xlfn.CONCAT(Tabela1[[#This Row],[Selecione o Usuário]]," - ",TEXT(Tabela1[[#This Row],[Informe a data]],"dd-mm-aa")) -> #NAME?
A9: 46029.817 | B9: camila.althoff@mazzini.com.br | C9: CAMILA CRISTINE ALTHOFF | D9: Mlz4j72 | E9: 46029 | F9: 185504 | G9: https://drive.google.com/open?id=1nu8DrNJy1dUm1K66c3HCTZe6fGl2tLQW | H9: 185564 | I9: https://drive.google.com/open?id=1jlVjfylpz2NIezjqJHpoirEvIE-GUOYy | J9: Carrefour, Fort campeche, hiperbom | L9: Sim | O9: 18.00 | P9: https://drive.google.com/open?id=1KRpYPCL0Bg4ZUqDw96dC0T4966CaXL56 | U9: =(Tabela1[[#This Row],[Informe o KM final do dia]]-Tabela1[[#This Row],[Informe o KM inicial do dia]])-Tabela1[[#This Row],[Caso tenha rodado particular alguma parte do trajeto, informe o total de KM a ser deduzido.]] -> 60 | V9: =IF(Tabela1[[#This Row],[Informe a data]]<DATE(2026,3,16), Tabela1[[#This Row],[KM Rodado]]*1.1, Tabela1[[#This Row],[KM Rodado]]*1.23) -> 66 | W9: =IFERROR(SUBSTITUTE(Tabela1[[#This Row],[Pedágio]],".",",",1)*1,0) -> 0 | X9: =IFERROR(SUBSTITUTE(Tabela1[[#This Row],[Estacionamento]],".",",",1)*1,0) -> 18 | Y9: =IFERROR(SUBSTITUTE(Tabela1[[#This Row],[Despesas Diversas (Jantar em viagem, Impressões, Etc)]],".",",",1)*1,0) -> 0 | Z9: =IFERROR(SUBSTITUTE(Tabela1[[#This Row],[Hospedagem]],".",",",1)*1,0) -> 0 | AA9: =IF(DAY(Tabela1[[#This Row],[Informe a data]])<=15,"1ª Quinzena","2ª Quinzena") -> 1ª Quinzena | AB9: =UPPER(TEXT(Tabela1[[#This Row],[Informe a data]],"mmmm")) -> JANEIRO | AC9: =_xlfn.CONCAT(Tabela1[[#This Row],[Selecione o Usuário]]," - ",TEXT(Tabela1[[#This Row],[Informe a data]],"dd-mm-aa")) -> #NAME?
A10: 46031.98 | B10: lombardi2025@gmail.com | C10: RICARDO ALEXANDRE LOMBARDI | D10: OWA4C07 | E10: 46029 | F10: 167625 | G10: https://drive.google.com/open?id=13Tk9wQ7CNu2Qz1Rl5J8AHAdp9iX6VT7S | H10: 167732 | I10: https://drive.google.com/open?id=1O4RuK3ZypLPzwDU6-2s90egzCtDsvh84 | J10: Komprao 50,Fort Tuiuti,condor comasa,Fort 405,brasil atacadista,bistek | L10: Não | U10: =(Tabela1[[#This Row],[Informe o KM final do dia]]-Tabela1[[#This Row],[Informe o KM inicial do dia]])-Tabela1[[#This Row],[Caso tenha rodado particular alguma parte do trajeto, informe o total de KM a ser deduzido.]] -> 107 | V10: =IF(Tabela1[[#This Row],[Informe a data]]<DATE(2026,3,16), Tabela1[[#This Row],[KM Rodado]]*1.1, Tabela1[[#This Row],[KM Rodado]]*1.23) -> 117.7 | W10: =IFERROR(SUBSTITUTE(Tabela1[[#This Row],[Pedágio]],".",",",1)*1,0) -> 0 | X10: =IFERROR(SUBSTITUTE(Tabela1[[#This Row],[Estacionamento]],".",",",1)*1,0) -> 0 | Y10: =IFERROR(SUBSTITUTE(Tabela1[[#This Row],[Despesas Diversas (Jantar em viagem, Impressões, Etc)]],".",",",1)*1,0) -> 0 | Z10: =IFERROR(SUBSTITUTE(Tabela1[[#This Row],[Hospedagem]],".",",",1)*1,0) -> 0 | AA10: =IF(DAY(Tabela1[[#This Row],[Informe a data]])<=15,"1ª Quinzena","2ª Quinzena") -> 1ª Quinzena | AB10: =UPPER(TEXT(Tabela1[[#This Row],[Informe a data]],"mmmm")) -> JANEIRO | AC10: =_xlfn.CONCAT(Tabela1[[#This Row],[Selecione o Usuário]]," - ",TEXT(Tabela1[[#This Row],[Informe a data]],"dd-mm-aa")) -> #NAME?
A11: 46034.356 | B11: sussuazevedo.com@icloud.com | C11: SUELEN DOS SANTOS AZEVEDO | D11: Mfw6d17 | E11: 46029 | F11: 105842 | G11: https://drive.google.com/open?id=1Lv9VwLe1pEbpf4veXfmkoHMXj5Nu63RI | H11: 105850 | I11: https://drive.google.com/open?id=1W_7KRYLgBEOvssy_t9Lq6wwpjmmZCYL8 | J11: Komprão 37 Komprão 15 Koch 7 koch41 | L11: Não | U11: =(Tabela1[[#This Row],[Informe o KM final do dia]]-Tabela1[[#This Row],[Informe o KM inicial do dia]])-Tabela1[[#This Row],[Caso tenha rodado particular alguma parte do trajeto, informe o total de KM a ser deduzido.]] -> 8 | V11: =IF(Tabela1[[#This Row],[Informe a data]]<DATE(2026,3,16), Tabela1[[#This Row],[KM Rodado]]*1.1, Tabela1[[#This Row],[KM Rodado]]*1.23) -> 8.8 | W11: =IFERROR(SUBSTITUTE(Tabela1[[#This Row],[Pedágio]],".",",",1)*1,0) -> 0 | X11: =IFERROR(SUBSTITUTE(Tabela1[[#This Row],[Estacionamento]],".",",",1)*1,0) -> 0 | Y11: =IFERROR(SUBSTITUTE(Tabela1[[#This Row],[Despesas Diversas (Jantar em viagem, Impressões, Etc)]],".",",",1)*1,0) -> 0 | Z11: =IFERROR(SUBSTITUTE(Tabela1[[#This Row],[Hospedagem]],".",",",1)*1,0) -> 0 | AA11: =IF(DAY(Tabela1[[#This Row],[Informe a data]])<=15,"1ª Quinzena","2ª Quinzena") -> 1ª Quinzena | AB11: =UPPER(TEXT(Tabela1[[#This Row],[Informe a data]],"mmmm")) -> JANEIRO | AC11: =_xlfn.CONCAT(Tabela1[[#This Row],[Selecione o Usuário]]," - ",TEXT(Tabela1[[#This Row],[Informe a data]],"dd-mm-aa")) -> #NAME?
A12: 46031.48 | B12: camila.althoff@mazzini.com.br | C12: CAMILA CRISTINE ALTHOFF | D12: Mlz4j72 | E12: 46030 | F12: 151395 | G12: https://drive.google.com/open?id=1N8h61bOZYLyYe638o3_mvWAkZ1VW-npk | H12: 151755 | I12: https://drive.google.com/open?id=1hVkqxc8cgkNRDt8iM6-MzIDN2mEP77Ny | J12: Pegar cestas no Gustavo , Komprao água verde | L12: Sim | M12: 11.40 | N12: https://drive.google.com/open?id=1Guh61Oyl3HFOTcLNSGv0mQH4V4J9ebRH | U12: =(Tabela1[[#This Row],[Informe o KM final do dia]]-Tabela1[[#This Row],[Informe o KM inicial do dia]])-Tabela1[[#This Row],[Caso tenha rodado particular alguma parte do trajeto, informe o total de KM a ser deduzido.]] -> 360 | V12: =IF(Tabela1[[#This Row],[Informe a data]]<DATE(2026,3,16), Tabela1[[#This Row],[KM Rodado]]*1.1, Tabela1[[#This Row],[KM Rodado]]*1.23) -> 396 | W12: =IFERROR(SUBSTITUTE(Tabela1[[#This Row],[Pedágio]],".",",",1)*1,0) -> 11.4 | X12: =IFERROR(SUBSTITUTE(Tabela1[[#This Row],[Estacionamento]],".",",",1)*1,0) -> 0 | Y12: =IFERROR(SUBSTITUTE(Tabela1[[#This Row],[Despesas Diversas (Jantar em viagem, Impressões, Etc)]],".",",",1)*1,0) -> 0 | Z12: =IFERROR(SUBSTITUTE(Tabela1[[#This Row],[Hospedagem]],".",",",1)*1,0) -> 0 | AA12: =IF(DAY(Tabela1[[#This Row],[Informe a data]])<=15,"1ª Quinzena","2ª Quinzena") -> 1ª Quinzena | AB12: =UPPER(TEXT(Tabela1[[#This Row],[Informe a data]],"mmmm")) -> JANEIRO | AC12: =_xlfn.CONCAT(Tabela1[[#This Row],[Selecione o Usuário]]," - ",TEXT(Tabela1[[#This Row],[Informe a data]],"dd-mm-aa")) -> #NAME?
A13: 46034.361 | B13: sussuazevedo.com@icloud.com | C13: SUELEN DOS SANTOS AZEVEDO | D13: Mfw6d17 | E13: 46030 | F13: 105891 | G13: https://drive.google.com/open?id=1nww-76sgilmMbg5PKFBpw5eOqVVpxeNJ | H13: 105938 | I13: https://drive.google.com/open?id=1aTeS1MXlIxnPeY_JKJTZMKpOA4IJmmOD | J13: For 825, koch8 Komprão 38 Mesck atacadista | L13: Não | U13: =(Tabela1[[#This Row],[Informe o KM final do dia]]-Tabela1[[#This Row],[Informe o KM inicial do dia]])-Tabela1[[#This Row],[Caso tenha rodado particular alguma parte do trajeto, informe o total de KM a ser deduzido.]] -> 47 | V13: =IF(Tabela1[[#This Row],[Informe a data]]<DATE(2026,3,16), Tabela1[[#This Row],[KM Rodado]]*1.1, Tabela1[[#This Row],[KM Rodado]]*1.23) -> 51.7 | W13: =IFERROR(SUBSTITUTE(Tabela1[[#This Row],[Pedágio]],".",",",1)*1,0) -> 0 | X13: =IFERROR(SUBSTITUTE(Tabela1[[#This Row],[Estacionamento]],".",",",1)*1,0) -> 0 | Y13: =IFERROR(SUBSTITUTE(Tabela1[[#This Row],[Despesas Diversas (Jantar em viagem, Impressões, Etc)]],".",",",1)*1,0) -> 0 | Z13: =IFERROR(SUBSTITUTE(Tabela1[[#This Row],[Hospedagem]],".",",",1)*1,0) -> 0 | AA13: =IF(DAY(Tabela1[[#This Row],[Informe a data]])<=15,"1ª Quinzena","2ª Quinzena") -> 1ª Quinzena | AB13: =UPPER(TEXT(Tabela1[[#This Row],[Informe a data]],"mmmm")) -> JANEIRO | AC13: =_xlfn.CONCAT(Tabela1[[#This Row],[Selecione o Usuário]]," - ",TEXT(Tabela1[[#This Row],[Informe a data]],"dd-mm-aa")) -> #NAME?
A14: 46031.758 | B14: camila.althoff@mazzini.com.br | C14: CAMILA CRISTINE ALTHOFF | D14: Mlz4j72 | E14: 46031 | F14: 185564 | G14: https://drive.google.com/open?id=1uzoPl2u_v3TRDwT7CiimpjRgjU6IF71D | H14: 185593 | I14: https://drive.google.com/open?id=13VL6tqGt62MStI6lcmKByqH6oj5p-j_C | J14: Bistek costeira, brasil atacadista rio Tavares | L14: Não | U14: =(Tabela1[[#This Row],[Informe o KM final do dia]]-Tabela1[[#This Row],[Informe o KM inicial do dia]])-Tabela1[[#This Row],[Caso tenha rodado particular alguma parte do trajeto, informe o total de KM a ser deduzido.]] -> 29 | V14: =IF(Tabela1[[#This Row],[Informe a data]]<DATE(2026,3,16), Tabela1[[#This Row],[KM Rodado]]*1.1, Tabela1[[#This Row],[KM Rodado]]*1.23) -> 31.9 | W14: =IFERROR(SUBSTITUTE(Tabela1[[#This Row],[Pedágio]],".",",",1)*1,0) -> 0 | X14: =IFERROR(SUBSTITUTE(Tabela1[[#This Row],[Estacionamento]],".",",",1)*1,0) -> 0 | Y14: =IFERROR(SUBSTITUTE(Tabela1[[#This Row],[Despesas Diversas (Jantar em viagem, Impressões, Etc)]],".",",",1)*1,0) -> 0 | Z14: =IFERROR(SUBSTITUTE(Tabela1[[#This Row],[Hospedagem]],".",",",1)*1,0) -> 0 | AA14: =IF(DAY(Tabela1[[#This Row],[Informe a data]])<=15,"1ª Quinzena","2ª Quinzena") -> 1ª Quinzena | AB14: =UPPER(TEXT(Tabela1[[#This Row],[Informe a data]],"mmmm")) -> JANEIRO | AC14: =_xlfn.CONCAT(Tabela1[[#This Row],[Selecione o Usuário]]," - ",TEXT(Tabela1[[#This Row],[Informe a data]],"dd-mm-aa")) -> #NAME?
A15: 46031.988 | B15: lombardi2025@gmail.com | C15: RICARDO ALEXANDRE LOMBARDI | D15: OWA4C07 | E15: 46031 | F15: 167982 | G15: https://drive.google.com/open?id=1EYJ6QRpiYfbCGFKOqjwbU3b0LUP7Webn | H15: 168055 | I15: https://drive.google.com/open?id=1Pv7PHyKh379ZcICWKER-DUXXweGmaEWk | J15: Fort 250,sams club,Fort 905, komprao 51,condor 51,angeloni23, Angeloni 22 | L15: Não | U15: =(Tabela1[[#This Row],[Informe o KM final do dia]]-Tabela1[[#This Row],[Informe o KM inicial do dia]])-Tabela1[[#This Row],[Caso tenha rodado particular alguma parte do trajeto, informe o total de KM a ser deduzido.]] -> 73 | V15: =IF(Tabela1[[#This Row],[Informe a data]]<DATE(2026,3,16), Tabela1[[#This Row],[KM Rodado]]*1.1, Tabela1[[#This Row],[KM Rodado]]*1.23) -> 80.3 | W15: =IFERROR(SUBSTITUTE(Tabela1[[#This Row],[Pedágio]],".",",",1)*1,0) -> 0 | X15: =IFERROR(SUBSTITUTE(Tabela1[[#This Row],[Estacionamento]],".",",",1)*1,0) -> 0 | Y15: =IFERROR(SUBSTITUTE(Tabela1[[#This Row],[Despesas Diversas (Jantar em viagem, Impressões, Etc)]],".",",",1)*1,0) -> 0 | Z15: =IFERROR(SUBSTITUTE(Tabela1[[#This Row],[Hospedagem]],".",",",1)*1,0) -> 0 | AA15: =IF(DAY(Tabela1[[#This Row],[Informe a data]])<=15,"1ª Quinzena","2ª Quinzena") -> 1ª Quinzena | AB15: =UPPER(TEXT(Tabela1[[#This Row],[Informe a data]],"mmmm")) -> JANEIRO | AC15: =_xlfn.CONCAT(Tabela1[[#This Row],[Selecione o Usuário]]," - ",TEXT(Tabela1[[#This Row],[Informe a data]],"dd-mm-aa")) -> #NAME?
A16: 46031.745 | B16: sabrina.pires@mazzi.com.br | C16: SABRINA DOS SANTOS PIRES | D16: Azc9e32 | E16: 46031 | F16: 172907 | G16: https://drive.google.com/open?id=1w8M7KRWc8d4SWhuRpo7t2gcKbbEX8u2Q | H16: 173040 | I16: https://drive.google.com/open?id=1GU8YE6ECr8FFpdYMIRO0m10_rAk_g2Tk | J16: Komprao Tijucas Komprao Tijucas Fort 290 Fort 365 Komprao avenida das torres | L16: Não | U16: =(Tabela1[[#This Row],[Informe o KM final do dia]]-Tabela1[[#This Row],[Informe o KM inicial do dia]])-Tabela1[[#This Row],[Caso tenha rodado particular alguma parte do trajeto, informe o total de KM a ser deduzido.]] -> 133 | V16: =IF(Tabela1[[#This Row],[Informe a data]]<DATE(2026,3,16), Tabela1[[#This Row],[KM Rodado]]*1.1, Tabela1[[#This Row],[KM Rodado]]*1.23) -> 146.3 | W16: =IFERROR(SUBSTITUTE(Tabela1[[#This Row],[Pedágio]],".",",",1)*1,0) -> 0 | X16: =IFERROR(SUBSTITUTE(Tabela1[[#This Row],[Estacionamento]],".",",",1)*1,0) -> 0 | Y16: =IFERROR(SUBSTITUTE(Tabela1[[#This Row],[Despesas Diversas (Jantar em viagem, Impressões, Etc)]],".",",",1)*1,0) -> 0 | Z16: =IFERROR(SUBSTITUTE(Tabela1[[#This Row],[Hospedagem]],".",",",1)*1,0) -> 0 | AA16: =IF(DAY(Tabela1[[#This Row],[Informe a data]])<=15,"1ª Quinzena","2ª Quinzena") -> 1ª Quinzena | AB16: =UPPER(TEXT(Tabela1[[#This Row],[Informe a data]],"mmmm")) -> JANEIRO | AC16: =_xlfn.CONCAT(Tabela1[[#This Row],[Selecione o Usuário]]," - ",TEXT(Tabela1[[#This Row],[Informe a data]],"dd-mm-aa")) -> #NAME?
A17: 46035.388 | B17: camila.althoff@mazzini.com.br | C17: CAMILA CRISTINE ALTHOFF | D17: Mlz4j72 | E17: 46034 | F17: 185599 | G17: https://drive.google.com/open?id=1PD2xpvm1rXxZHPud1C3wTfxyW1LZ6IfH | H17: 185643 | I17: https://drive.google.com/open?id=12ra3N6T7q3FTSitBav3bT5myvEQJn6EA | J17: Fort 810, Fort 210 recolha de EPI Everton | L17: Não | U17: =(Tabela1[[#This Row],[Informe o KM final do dia]]-Tabela1[[#This Row],[Informe o KM inicial do dia]])-Tabela1[[#This Row],[Caso tenha rodado particular alguma parte do trajeto, informe o total de KM a ser deduzido.]] -> 44 | V17: =IF(Tabela1[[#This Row],[Informe a data]]<DATE(2026,3,16), Tabela1[[#This Row],[KM Rodado]]*1.1, Tabela1[[#This Row],[KM Rodado]]*1.23) -> 48.4 | W17: =IFERROR(SUBSTITUTE(Tabela1[[#This Row],[Pedágio]],".",",",1)*1,0) -> 0 | X17: =IFERROR(SUBSTITUTE(Tabela1[[#This Row],[Estacionamento]],".",",",1)*1,0) -> 0 | Y17: =IFERROR(SUBSTITUTE(Tabela1[[#This Row],[Despesas Diversas (Jantar em viagem, Impressões, Etc)]],".",",",1)*1,0) -> 0 | Z17: =IFERROR(SUBSTITUTE(Tabela1[[#This Row],[Hospedagem]],".",",",1)*1,0) -> 0 | AA17: =IF(DAY(Tabela1[[#This Row],[Informe a data]])<=15,"1ª Quinzena","2ª Quinzena") -> 1ª Quinzena | AB17: =UPPER(TEXT(Tabela1[[#This Row],[Informe a data]],"mmmm")) -> JANEIRO | AC17: =_xlfn.CONCAT(Tabela1[[#This Row],[Selecione o Usuário]]," - ",TEXT(Tabela1[[#This Row],[Informe a data]],"dd-mm-aa")) -> #NAME?
A18: 46035.806 | B18: michalski.ep@gmail.com | C18: ANDERSON MICHALSKI FERREIRA | D18: BCS7I80 | E18: 46035 | F18: 221889 | G18: https://drive.google.com/open?id=1pY4X-HNwcWapgYXMxlW2TZSFjG7D-bFY | H18: 221889 | I18: https://drive.google.com/open?id=1zat7qCqFXVcvF9Vql4O6T1qr74Nv5U06 | J18: ENVIO UNIFORMES | L18: Sim | Q18: 179.49 | R18: https://drive.google.com/open?id=14UEk1IkpAGmVOjXL4tfliK5-_9GinfaW | T18: Envio de Uniformes | U18: =(Tabela1[[#This Row],[Informe o KM final do dia]]-Tabela1[[#This Row],[Informe o KM inicial do dia]])-Tabela1[[#This Row],[Caso tenha rodado particular alguma parte do trajeto, informe o total de KM a ser deduzido.]] -> 0 | V18: =IF(Tabela1[[#This Row],[Informe a data]]<DATE(2026,3,16), Tabela1[[#This Row],[KM Rodado]]*1.1, Tabela1[[#This Row],[KM Rodado]]*1.23) -> 0 | W18: =IFERROR(SUBSTITUTE(Tabela1[[#This Row],[Pedágio]],".",",",1)*1,0) -> 0 | X18: =IFERROR(SUBSTITUTE(Tabela1[[#This Row],[Estacionamento]],".",",",1)*1,0) -> 0 | Y18: =IFERROR(SUBSTITUTE(Tabela1[[#This Row],[Despesas Diversas (Jantar em viagem, Impressões, Etc)]],".",",",1)*1,0) -> 179.49 | Z18: =IFERROR(SUBSTITUTE(Tabela1[[#This Row],[Hospedagem]],".",",",1)*1,0) -> 0 | AA18: =IF(DAY(Tabela1[[#This Row],[Informe a data]])<=15,"1ª Quinzena","2ª Quinzena") -> 1ª Quinzena | AB18: =UPPER(TEXT(Tabela1[[#This Row],[Informe a data]],"mmmm")) -> JANEIRO | AC18: =_xlfn.CONCAT(Tabela1[[#This Row],[Selecione o Usuário]]," - ",TEXT(Tabela1[[#This Row],[Informe a data]],"dd-mm-aa")) -> #NAME?
A19: 46035.762 | B19: oliiveiiraa7@gmail.com | C19: GUSTAVO MATHEUS DE OLIVEIRA | D19: EUF3090 | E19: 46035 | F19: 158913 | G19: https://drive.google.com/open?id=1-0BhC6YDZNaDTaBYS-i_TdgNBmUCwkLh | H19: 159149 | I19: https://drive.google.com/open?id=1eTlOZEu-_eFXyU2Z6kWjIh1j53F8YX66 | J19: Deslocamento Fort Chapeco | L19: Sim | S19: 219.94 | U19: =(Tabela1[[#This Row],[Informe o KM final do dia]]-Tabela1[[#This Row],[Informe o KM inicial do dia]])-Tabela1[[#This Row],[Caso tenha rodado particular alguma parte do trajeto, informe o total de KM a ser deduzido.]] -> 236 | V19: =IF(Tabela1[[#This Row],[Informe a data]]<DATE(2026,3,16), Tabela1[[#This Row],[KM Rodado]]*1.1, Tabela1[[#This Row],[KM Rodado]]*1.23) -> 259.6 | W19: =IFERROR(SUBSTITUTE(Tabela1[[#This Row],[Pedágio]],".",",",1)*1,0) -> 0 | X19: =IFERROR(SUBSTITUTE(Tabela1[[#This Row],[Estacionamento]],".",",",1)*1,0) -> 0 | Y19: =IFERROR(SUBSTITUTE(Tabela1[[#This Row],[Despesas Diversas (Jantar em viagem, Impressões, Etc)]],".",",",1)*1,0) -> 0 | Z19: =IFERROR(SUBSTITUTE(Tabela1[[#This Row],[Hospedagem]],".",",",1)*1,0) -> 219.94 | AA19: =IF(DAY(Tabela1[[#This Row],[Informe a data]])<=15,"1ª Quinzena","2ª Quinzena") -> 1ª Quinzena | AB19: =UPPER(TEXT(Tabela1[[#This Row],[Informe a data]],"mmmm")) -> JANEIRO | AC19: =_xlfn.CONCAT(Tabela1[[#This Row],[Selecione o Usuário]]," - ",TEXT(Tabela1[[#This Row],[Informe a data]],"dd-mm-aa")) -> #NAME?
A20: 46037.341 | B20: camila.althoff@mazzini.com.br | C20: CAMILA CRISTINE ALTHOFF | D20: Mlz4j72 | E20: 46036 | F20: 185662 | G20: https://drive.google.com/open?id=16bd2a0wg_uF7OIU-LmS20gupyXxpzxIU | H20: 185709 | I20: https://drive.google.com/open?id=1tNU22_rmd6TpdcXyoKtNGmjrsJ-Clovg | J20: Angeloni beira mar, atacadão via expressa, Angeloni capoeiras, Fort jardim atlântico | L20: Não | U20: =(Tabela1[[#This Row],[Informe o KM final do dia]]-Tabela1[[#This Row],[Informe o KM inicial do dia]])-Tabela1[[#This Row],[Caso tenha rodado particular alguma parte do trajeto, informe o total de KM a ser deduzido.]] -> 47 | V20: =IF(Tabela1[[#This Row],[Informe a data]]<DATE(2026,3,16), Tabela1[[#This Row],[KM Rodado]]*1.1, Tabela1[[#This Row],[KM Rodado]]*1.23) -> 51.7 | W20: =IFERROR(SUBSTITUTE(Tabela1[[#This Row],[Pedágio]],".",",",1)*1,0) -> 0 | X20: =IFERROR(SUBSTITUTE(Tabela1[[#This Row],[Estacionamento]],".",",",1)*1,0) -> 0 | Y20: =IFERROR(SUBSTITUTE(Tabela1[[#This Row],[Despesas Diversas (Jantar em viagem, Impressões, Etc)]],".",",",1)*1,0) -> 0 | Z20: =IFERROR(SUBSTITUTE(Tabela1[[#This Row],[Hospedagem]],".",",",1)*1,0) -> 0 | AA20: =IF(DAY(Tabela1[[#This Row],[Informe a data]])<=15,"1ª Quinzena","2ª Quinzena") -> 1ª Quinzena | AB20: =UPPER(TEXT(Tabela1[[#This Row],[Informe a data]],"mmmm")) -> JANEIRO | AC20: =_xlfn.CONCAT(Tabela1[[#This Row],[Selecione o Usuário]]," - ",TEXT(Tabela1[[#This Row],[Informe a data]],"dd-mm-aa")) -> #NAME?
A21: 46036.701 | B21: desyree.gaulke@mazzini.com.br | C21: Desyree Yasmin Gaulke Klebber | D21: QIL7H04 | E21: 46036 | F21: 117269 | G21: https://drive.google.com/open?id=1nz6okC6pw3Hytv7RaIvWfyGnNfWJOTzr | H21: 117506 | I21: https://drive.google.com/open?id=1RZEvaf1DkVshquScw34MBQcU0dyx3zhX | J21: BR ATACADISTA RIO DO SUL, FORT 255, COOPER IBIRAMA, COOPER RODEIO, MOCAM 403 | L21: Não | U21: =(Tabela1[[#This Row],[Informe o KM final do dia]]-Tabela1[[#This Row],[Informe o KM inicial do dia]])-Tabela1[[#This Row],[Caso tenha rodado particular alguma parte do trajeto, informe o total de KM a ser deduzido.]] -> 237 | V21: =IF(Tabela1[[#This Row],[Informe a data]]<DATE(2026,3,16), Tabela1[[#This Row],[KM Rodado]]*1.1, Tabela1[[#This Row],[KM Rodado]]*1.23) -> 260.7 | W21: =IFERROR(SUBSTITUTE(Tabela1[[#This Row],[Pedágio]],".",",",1)*1,0) -> 0 | X21: =IFERROR(SUBSTITUTE(Tabela1[[#This Row],[Estacionamento]],".",",",1)*1,0) -> 0 | Y21: =IFERROR(SUBSTITUTE(Tabela1[[#This Row],[Despesas Diversas (Jantar em viagem, Impressões, Etc)]],".",",",1)*1,0) -> 0 | Z21: =IFERROR(SUBSTITUTE(Tabela1[[#This Row],[Hospedagem]],".",",",1)*1,0) -> 0 | AA21: =IF(DAY(Tabela1[[#This Row],[Informe a data]])<=15,"1ª Quinzena","2ª Quinzena") -> 1ª Quinzena | AB21: =UPPER(TEXT(Tabela1[[#This Row],[Informe a data]],"mmmm")) -> JANEIRO | AC21: =_xlfn.CONCAT(Tabela1[[#This Row],[Selecione o Usuário]]," - ",TEXT(Tabela1[[#This Row],[Informe a data]],"dd-mm-aa")) -> #NAME?
A22: 46036.801 | B22: oliiveiiraa7@gmail.com | C22: GUSTAVO MATHEUS DE OLIVEIRA | D22: EUF3090 | E22: 46036 | F22: 159149 | G22: https://drive.google.com/open?id=16FEsnAg4spPtqAvXuKezJfoX9qMUTrxh | H22: 159414 | I22: https://drive.google.com/open?id=16dO2AfLsy6iNzerGw4qIUYD3XtSLz_uj | J22: Fort Chapeco, Atacadao avenida senador, Atacadao Chapecó e deslocamento | L22: Não | U22: =(Tabela1[[#This Row],[Informe o KM final do dia]]-Tabela1[[#This Row],[Informe o KM inicial do dia]])-Tabela1[[#This Row],[Caso tenha rodado particular alguma parte do trajeto, informe o total de KM a ser deduzido.]] -> 265 | V22: =IF(Tabela1[[#This Row],[Informe a data]]<DATE(2026,3,16), Tabela1[[#This Row],[KM Rodado]]*1.1, Tabela1[[#This Row],[KM Rodado]]*1.23) -> 291.5 | W22: =IFERROR(SUBSTITUTE(Tabela1[[#This Row],[Pedágio]],".",",",1)*1,0) -> 0 | X22: =IFERROR(SUBSTITUTE(Tabela1[[#This Row],[Estacionamento]],".",",",1)*1,0) -> 0 | Y22: =IFERROR(SUBSTITUTE(Tabela1[[#This Row],[Despesas Diversas (Jantar em viagem, Impressões, Etc)]],".",",",1)*1,0) -> 0 | Z22: =IFERROR(SUBSTITUTE(Tabela1[[#This Row],[Hospedagem]],".",",",1)*1,0) -> 0 | AA22: =IF(DAY(Tabela1[[#This Row],[Informe a data]])<=15,"1ª Quinzena","2ª Quinzena") -> 1ª Quinzena | AB22: =UPPER(TEXT(Tabela1[[#This Row],[Informe a data]],"mmmm")) -> JANEIRO | AC22: =_xlfn.CONCAT(Tabela1[[#This Row],[Selecione o Usuário]]," - ",TEXT(Tabela1[[#This Row],[Informe a data]],"dd-mm-aa")) -> #NAME?
A23: 46036.828 | B23: lombardi2025@gmail.com | C23: RICARDO ALEXANDRE LOMBARDI | D23: OWA4C07 | E23: 46036 | F23: 168113 | G23: https://drive.google.com/open?id=11IodFoCASvGaTdCmPaFQav7G8cFHYRiO | H23: 168215 | I23: https://drive.google.com/open?id=1up7n9UC13aQd1uK_4ItlyH7EBGOPv3Tq | J23: Komprao 51,brasil atacadista,condor comasa,casa Leandro,Fort Tuiuti,komprao 45,Fort 405,fort 905, komprao 50,Fort 250 | L23: Não | U23: =(Tabela1[[#This Row],[Informe o KM final do dia]]-Tabela1[[#This Row],[Informe o KM inicial do dia]])-Tabela1[[#This Row],[Caso tenha rodado particular alguma parte do trajeto, informe o total de KM a ser deduzido.]] -> 102 | V23: =IF(Tabela1[[#This Row],[Informe a data]]<DATE(2026,3,16), Tabela1[[#This Row],[KM Rodado]]*1.1, Tabela1[[#This Row],[KM Rodado]]*1.23) -> 112.2 | W23: =IFERROR(SUBSTITUTE(Tabela1[[#This Row],[Pedágio]],".",",",1)*1,0) -> 0 | X23: =IFERROR(SUBSTITUTE(Tabela1[[#This Row],[Estacionamento]],".",",",1)*1,0) -> 0 | Y23: =IFERROR(SUBSTITUTE(Tabela1[[#This Row],[Despesas Diversas (Jantar em viagem, Impressões, Etc)]],".",",",1)*1,0) -> 0 | Z23: =IFERROR(SUBSTITUTE(Tabela1[[#This Row],[Hospedagem]],".",",",1)*1,0) -> 0 | AA23: =IF(DAY(Tabela1[[#This Row],[Informe a data]])<=15,"1ª Quinzena","2ª Quinzena") -> 1ª Quinzena | AB23: =UPPER(TEXT(Tabela1[[#This Row],[Informe a data]],"mmmm")) -> JANEIRO | AC23: =_xlfn.CONCAT(Tabela1[[#This Row],[Selecione o Usuário]]," - ",TEXT(Tabela1[[#This Row],[Informe a data]],"dd-mm-aa")) -> #NAME?
A24: 46036.701 | B24: sabrina.pires@mazzini.com.br | C24: SABRINA DOS SANTOS PIRES | D24: azc9e32 | E24: 46036 | F24: 173277 | G24: https://drive.google.com/open?id=1lmqkqJRGldxk0YxFfRrgFuSTY3Ktp8AU | H24: 173401 | I24: https://drive.google.com/open?id=1_80jiqas8NG0LqhrPML0Aggj06tdFzCj | J24: Fort biguaçu Komprao não viver Fort barreiros Fort São José Komprao forquilhas Komprao ponte do imaruim | L24: Não | U24: =(Tabela1[[#This Row],[Informe o KM final do dia]]-Tabela1[[#This Row],[Informe o KM inicial do dia]])-Tabela1[[#This Row],[Caso tenha rodado particular alguma parte do trajeto, informe o total de KM a ser deduzido.]] -> 124 | V24: =IF(Tabela1[[#This Row],[Informe a data]]<DATE(2026,3,16), Tabela1[[#This Row],[KM Rodado]]*1.1, Tabela1[[#This Row],[KM Rodado]]*1.23) -> 136.4 | W24: =IFERROR(SUBSTITUTE(Tabela1[[#This Row],[Pedágio]],".",",",1)*1,0) -> 0 | X24: =IFERROR(SUBSTITUTE(Tabela1[[#This Row],[Estacionamento]],".",",",1)*1,0) -> 0 | Y24: =IFERROR(SUBSTITUTE(Tabela1[[#This Row],[Despesas Diversas (Jantar em viagem, Impressões, Etc)]],".",",",1)*1,0) -> 0 | Z24: =IFERROR(SUBSTITUTE(Tabela1[[#This Row],[Hospedagem]],".",",",1)*1,0) -> 0 | AA24: =IF(DAY(Tabela1[[#This Row],[Informe a data]])<=15,"1ª Quinzena","2ª Quinzena") -> 1ª Quinzena | AB24: =UPPER(TEXT(Tabela1[[#This Row],[Informe a data]],"mmmm")) -> JANEIRO | AC24: =_xlfn.CONCAT(Tabela1[[#This Row],[Selecione o Usuário]]," - ",TEXT(Tabela1[[#This Row],[Informe a data]],"dd-mm-aa")) -> #NAME?
A25: 46037.841 | B25: camila.althoff@mazzini.com.br | C25: CAMILA CRISTINE ALTHOFF | D25: Mlz4j72 | E25: 46037 | F25: 185709 | G25: https://drive.google.com/open?id=1HtVmdAdVtxxwySruCnc5U9ynTf37Nim3 | H25: 185799 | I25: https://drive.google.com/open?id=1qAppb28zIO0xulaZKQeSzkNaZ3Kbu7yS | J25: Zeus brasil, imperatriz Lagoa, Fort campeche | L25: Não | U25: =(Tabela1[[#This Row],[Informe o KM final do dia]]-Tabela1[[#This Row],[Informe o KM inicial do dia]])-Tabela1[[#This Row],[Caso tenha rodado particular alguma parte do trajeto, informe o total de KM a ser deduzido.]] -> 90 | V25: =IF(Tabela1[[#This Row],[Informe a data]]<DATE(2026,3,16), Tabela1[[#This Row],[KM Rodado]]*1.1, Tabela1[[#This Row],[KM Rodado]]*1.23) -> 99 | W25: =IFERROR(SUBSTITUTE(Tabela1[[#This Row],[Pedágio]],".",",",1)*1,0) -> 0 | X25: =IFERROR(SUBSTITUTE(Tabela1[[#This Row],[Estacionamento]],".",",",1)*1,0) -> 0 | Y25: =IFERROR(SUBSTITUTE(Tabela1[[#This Row],[Despesas Diversas (Jantar em viagem, Impressões, Etc)]],".",",",1)*1,0) -> 0 | Z25: =IFERROR(SUBSTITUTE(Tabela1[[#This Row],[Hospedagem]],".",",",1)*1,0) -> 0 | AA25: =IF(DAY(Tabela1[[#This Row],[Informe a data]])<=15,"1ª Quinzena","2ª Quinzena") -> 1ª Quinzena | AB25: =UPPER(TEXT(Tabela1[[#This Row],[Informe a data]],"mmmm")) -> JANEIRO | AC25: =_xlfn.CONCAT(Tabela1[[#This Row],[Selecione o Usuário]]," - ",TEXT(Tabela1[[#This Row],[Informe a data]],"dd-mm-aa")) -> #NAME?
A26: 46037.741 | B26: desyree.gaulke@mazzini.com.br | C26: Desyree Yasmin Gaulke Klebber | D26: QIL7H04 | E26: 46037 | F26: 117508 | G26: https://drive.google.com/open?id=101YYzxtGhhUZ9p_cFBoQcP8EThwSx9GX | H26: 117599 | I26: https://drive.google.com/open?id=12e1B5poMUOhkR8Ws6y2_UnsnzhxKEoGS | J26: central 101, brasil atacadista, bisteck park europeu e central 103 | L26: Não | U26: =(Tabela1[[#This Row],[Informe o KM final do dia]]-Tabela1[[#This Row],[Informe o KM inicial do dia]])-Tabela1[[#This Row],[Caso tenha rodado particular alguma parte do trajeto, informe o total de KM a ser deduzido.]] -> 91 | V26: =IF(Tabela1[[#This Row],[Informe a data]]<DATE(2026,3,16), Tabela1[[#This Row],[KM Rodado]]*1.1, Tabela1[[#This Row],[KM Rodado]]*1.23) -> 100.1 | W26: =IFERROR(SUBSTITUTE(Tabela1[[#This Row],[Pedágio]],".",",",1)*1,0) -> 0 | X26: =IFERROR(SUBSTITUTE(Tabela1[[#This Row],[Estacionamento]],".",",",1)*1,0) -> 0 | Y26: =IFERROR(SUBSTITUTE(Tabela1[[#This Row],[Despesas Diversas (Jantar em viagem, Impressões, Etc)]],".",",",1)*1,0) -> 0 | Z26: =IFERROR(SUBSTITUTE(Tabela1[[#This Row],[Hospedagem]],".",",",1)*1,0) -> 0 | AA26: =IF(DAY(Tabela1[[#This Row],[Informe a data]])<=15,"1ª Quinzena","2ª Quinzena") -> 1ª Quinzena | AB26: =UPPER(TEXT(Tabela1[[#This Row],[Informe a data]],"mmmm")) -> JANEIRO | AC26: =_xlfn.CONCAT(Tabela1[[#This Row],[Selecione o Usuário]]," - ",TEXT(Tabela1[[#This Row],[Informe a data]],"dd-mm-aa")) -> #NAME?
A27: 46031.984 | B27: lombardi2025@gmail.com | C27: RICARDO ALEXANDRE LOMBARDI | D27: OWA4C07 | E27: 46037 | F27: 167732 | G27: https://drive.google.com/open?id=1AXvwZRv892_hprYewYcHXx84QHYr1qH7 | H27: 167982 | I27: https://drive.google.com/open?id=1Q1_kRkJ2sX-7oQ3DBRYM7fdiwltKBH1h | J27: Blumenau buscar cestas | L27: Não | U27: =(Tabela1[[#This Row],[Informe o KM final do dia]]-Tabela1[[#This Row],[Informe o KM inicial do dia]])-Tabela1[[#This Row],[Caso tenha rodado particular alguma parte do trajeto, informe o total de KM a ser deduzido.]] -> 250 | V27: =IF(Tabela1[[#This Row],[Informe a data]]<DATE(2026,3,16), Tabela1[[#This Row],[KM Rodado]]*1.1, Tabela1[[#This Row],[KM Rodado]]*1.23) -> 275 | W27: =IFERROR(SUBSTITUTE(Tabela1[[#This Row],[Pedágio]],".",",",1)*1,0) -> 0 | X27: =IFERROR(SUBSTITUTE(Tabela1[[#This Row],[Estacionamento]],".",",",1)*1,0) -> 0 | Y27: =IFERROR(SUBSTITUTE(Tabela1[[#This Row],[Despesas Diversas (Jantar em viagem, Impressões, Etc)]],".",",",1)*1,0) -> 0 | Z27: =IFERROR(SUBSTITUTE(Tabela1[[#This Row],[Hospedagem]],".",",",1)*1,0) -> 0 | AA27: =IF(DAY(Tabela1[[#This Row],[Informe a data]])<=15,"1ª Quinzena","2ª Quinzena") -> 1ª Quinzena | AB27: =UPPER(TEXT(Tabela1[[#This Row],[Informe a data]],"mmmm")) -> JANEIRO | AC27: =_xlfn.CONCAT(Tabela1[[#This Row],[Selecione o Usuário]]," - ",TEXT(Tabela1[[#This Row],[Informe a data]],"dd-mm-aa")) -> #NAME?
A28: 46039.758 | B28: lombardi2025@gmail.com | C28: RICARDO ALEXANDRE LOMBARDI | D28: OWA4C07 | E28: 46037 | F28: 168215 | G28: https://drive.google.com/open?id=1ouE6eSrVHXymBJFB_k3BeJ9XFnm1ToRH | H28: 168251 | I28: https://drive.google.com/open?id=1DC_zfbetQ_HfThKiu77mnGRCgZQkHqC- | J28: Komprao 51, brasil atacadista,condor comasa,Fort Tuiuti, imperatriz | L28: Não | U28: =(Tabela1[[#This Row],[Informe o KM final do dia]]-Tabela1[[#This Row],[Informe o KM inicial do dia]])-Tabela1[[#This Row],[Caso tenha rodado particular alguma parte do trajeto, informe o total de KM a ser deduzido.]] -> 36 | V28: =IF(Tabela1[[#This Row],[Informe a data]]<DATE(2026,3,16), Tabela1[[#This Row],[KM Rodado]]*1.1, Tabela1[[#This Row],[KM Rodado]]*1.23) -> 39.6 | W28: =IFERROR(SUBSTITUTE(Tabela1[[#This Row],[Pedágio]],".",",",1)*1,0) -> 0 | X28: =IFERROR(SUBSTITUTE(Tabela1[[#This Row],[Estacionamento]],".",",",1)*1,0) -> 0 | Y28: =IFERROR(SUBSTITUTE(Tabela1[[#This Row],[Despesas Diversas (Jantar em viagem, Impressões, Etc)]],".",",",1)*1,0) -> 0 | Z28: =IFERROR(SUBSTITUTE(Tabela1[[#This Row],[Hospedagem]],".",",",1)*1,0) -> 0 | AA28: =IF(DAY(Tabela1[[#This Row],[Informe a data]])<=15,"1ª Quinzena","2ª Quinzena") -> 1ª Quinzena | AB28: =UPPER(TEXT(Tabela1[[#This Row],[Informe a data]],"mmmm")) -> JANEIRO | AC28: =_xlfn.CONCAT(Tabela1[[#This Row],[Selecione o Usuário]]," - ",TEXT(Tabela1[[#This Row],[Informe a data]],"dd-mm-aa")) -> #NAME?
A29: 46037.748 | B29: sabrina.pires@mazzini.com.br | C29: SABRINA DOS SANTOS PIRES | D29: Azc9e32 | E29: 46037 | F29: 173440 | G29: https://drive.google.com/open?id=1u7-tiIgVHFBB-dnS3fN077IvI7wRDsav | H29: 173510 | I29: https://drive.google.com/open?id=1kjVJQKGP8CE_wSOOrJ3byhnLPdPhMi3S | J29: Komprao pedra branca Fort 130 Fort kobrasol Fort biguaçu Komprao forquilhas | L29: Não | U29: =(Tabela1[[#This Row],[Informe o KM final do dia]]-Tabela1[[#This Row],[Informe o KM inicial do dia]])-Tabela1[[#This Row],[Caso tenha rodado particular alguma parte do trajeto, informe o total de KM a ser deduzido.]] -> 70 | V29: =IF(Tabela1[[#This Row],[Informe a data]]<DATE(2026,3,16), Tabela1[[#This Row],[KM Rodado]]*1.1, Tabela1[[#This Row],[KM Rodado]]*1.23) -> 77 | W29: =IFERROR(SUBSTITUTE(Tabela1[[#This Row],[Pedágio]],".",",",1)*1,0) -> 0 | X29: =IFERROR(SUBSTITUTE(Tabela1[[#This Row],[Estacionamento]],".",",",1)*1,0) -> 0 | Y29: =IFERROR(SUBSTITUTE(Tabela1[[#This Row],[Despesas Diversas (Jantar em viagem, Impressões, Etc)]],".",",",1)*1,0) -> 0 | Z29: =IFERROR(SUBSTITUTE(Tabela1[[#This Row],[Hospedagem]],".",",",1)*1,0) -> 0 | AA29: =IF(DAY(Tabela1[[#This Row],[Informe a data]])<=15,"1ª Quinzena","2ª Quinzena") -> 1ª Quinzena | AB29: =UPPER(TEXT(Tabela1[[#This Row],[Informe a data]],"mmmm")) -> JANEIRO | AC29: =_xlfn.CONCAT(Tabela1[[#This Row],[Selecione o Usuário]]," - ",TEXT(Tabela1[[#This Row],[Informe a data]],"dd-mm-aa")) -> #NAME?
A30: 46038.382 | B30: suelen.azevedo@mazzini.com.br | C30: SUELEN DOS SANTOS AZEVEDO | D30: Mfw6D17 | E30: 46037 | F30: 105938 | G30: https://drive.google.com/open?id=1ilqg8CyOvxRY6w9pWkwxvgP4QbgbeQua | H30: 105978 | I30: https://drive.google.com/open?id=1Xwh5s0I9SNmtUAS_XuxJyxhOPUmUXXpB | J30: Fui na loja 9 loja 82 loja 4 | L30: Não | U30: =(Tabela1[[#This Row],[Informe o KM final do dia]]-Tabela1[[#This Row],[Informe o KM inicial do dia]])-Tabela1[[#This Row],[Caso tenha rodado particular alguma parte do trajeto, informe o total de KM a ser deduzido.]] -> 40 | V30: =IF(Tabela1[[#This Row],[Informe a data]]<DATE(2026,3,16), Tabela1[[#This Row],[KM Rodado]]*1.1, Tabela1[[#This Row],[KM Rodado]]*1.23) -> 44 | W30: =IFERROR(SUBSTITUTE(Tabela1[[#This Row],[Pedágio]],".",",",1)*1,0) -> 0 | X30: =IFERROR(SUBSTITUTE(Tabela1[[#This Row],[Estacionamento]],".",",",1)*1,0) -> 0 | Y30: =IFERROR(SUBSTITUTE(Tabela1[[#This Row],[Despesas Diversas (Jantar em viagem, Impressões, Etc)]],".",",",1)*1,0) -> 0 | Z30: =IFERROR(SUBSTITUTE(Tabela1[[#This Row],[Hospedagem]],".",",",1)*1,0) -> 0 | AA30: =IF(DAY(Tabela1[[#This Row],[Informe a data]])<=15,"1ª Quinzena","2ª Quinzena") -> 1ª Quinzena | AB30: =UPPER(TEXT(Tabela1[[#This Row],[Informe a data]],"mmmm")) -> JANEIRO | AC30: =_xlfn.CONCAT(Tabela1[[#This Row],[Selecione o Usuário]]," - ",TEXT(Tabela1[[#This Row],[Informe a data]],"dd-mm-aa")) -> #NAME?
A31: 46038.797 | B31: camila.althoff@mazzini.com.br | C31: CAMILA CRISTINE ALTHOFF | D31: Mlz4j72 | E31: 46038 | F31: 185799 | G31: https://drive.google.com/open?id=1401-bPasXzKWnHL16uoAMKuHzbbHBrth | H31: 185861 | I31: https://drive.google.com/open?id=1qgfZWCYwxANbzSC53-QTKV1hcgVhP-eK | J31: Angeloni beira mar, Fort vargem, kock 47 | L31: Não | U31: =(Tabela1[[#This Row],[Informe o KM final do dia]]-Tabela1[[#This Row],[Informe o KM inicial do dia]])-Tabela1[[#This Row],[Caso tenha rodado particular alguma parte do trajeto, informe o total de KM a ser deduzido.]] -> 62 | V31: =IF(Tabela1[[#This Row],[Informe a data]]<DATE(2026,3,16), Tabela1[[#This Row],[KM Rodado]]*1.1, Tabela1[[#This Row],[KM Rodado]]*1.23) -> 68.2 | W31: =IFERROR(SUBSTITUTE(Tabela1[[#This Row],[Pedágio]],".",",",1)*1,0) -> 0 | X31: =IFERROR(SUBSTITUTE(Tabela1[[#This Row],[Estacionamento]],".",",",1)*1,0) -> 0 | Y31: =IFERROR(SUBSTITUTE(Tabela1[[#This Row],[Despesas Diversas (Jantar em viagem, Impressões, Etc)]],".",",",1)*1,0) -> 0 | Z31: =IFERROR(SUBSTITUTE(Tabela1[[#This Row],[Hospedagem]],".",",",1)*1,0) -> 0 | AA31: =IF(DAY(Tabela1[[#This Row],[Informe a data]])<=15,"1ª Quinzena","2ª Quinzena") -> 2ª Quinzena | AB31: =UPPER(TEXT(Tabela1[[#This Row],[Informe a data]],"mmmm")) -> JANEIRO | AC31: =_xlfn.CONCAT(Tabela1[[#This Row],[Selecione o Usuário]]," - ",TEXT(Tabela1[[#This Row],[Informe a data]],"dd-mm-aa")) -> #NAME?
